Workbook
Name Origin: OFFSET(#REF!, 0, 0, COUNTA(#REF!))
Name Origin: OFFSET(#REF!, 0, 0, COUNTA(#REF!))
Name Origin: OFFSET(#REF!, 0, 0, COUNTA(#REF!))
Name Origin: OFFSET(#REF!, 0, 0, COUNTA(#REF!))
Name Origin: OFFSET(#REF!, 0, 0, COUNTA(#REF!))
Name Origin: OFFSET(#REF!, 0, 0, COUNTA(#REF!))
Name Origin: OFFSET(#REF!, 0, 0, COUNTA(#REF!))
Name Origin: OFFSET(Tariff!$G$8:$G$510, 0, 0, COUNTA(Tariff!$G$8:$G$510))

Sheet Cover Page

Sheet Conditions
B1: Conditions | I1: Vanguard Logistics Import LCL Tariff
B3: General
B5: Rates are subject to additional Bunker/Fuel costs associated with IMO/MARPOL 2020 Low Sulphur Measures.
B6: All rates shown in this pricing schedule are in US dollars unless otherwise stated.
B7: Other origins that do not appear in this Pricing Schedule may be available upon request. Please check with your local branches
B8: Ocean Freight Rates quoted herein cover general cargo only and freight that does not exceed 5.7 meters in length & 2.2 meters in height, any freight exceeding this must be advised prior to the booking of the freight. (Excluding Japan origin. Refer to Overdimensional surcharge Condition).
B9: All rates quoted are on a depot to depot basis. Please note that there will be import charges at destination ports and export charges at origin ports.
B10: Rates covering cargo transhipped outside Australia are inclusive of all transhipment costs.
B11: All rates are charged on a revenue tonnage basis. Either per cbm, per 1000kgs or Minimum which ever is the greater revenue.
B12: Any shipment weighing above 5 metric tonne will be charged at high density weight ratio. This ratio varies and is available at time of booking.
B13: All business undertaken is subject to the Company's Standard Trading Conditions, which may limit or exclude the Company's liability and contain indemnities benefiting the Company, copies of which are available upon request.
B14: Subject to Penalty fees/ surcharges imposed by the Carrier for misdeclared and non-compliant cargo.
B15: Open Coload fee of USD50.00 per B/L applicable on all relevant shipments.
... B21: Emergency Fuel Surcharge - Subject to change with / without notice.
B23: Origins | C23: Service | D23: Amount w/m Minimum | E23: Cargo Received or Arrived On or After
B24: All USA Origins | C24: Direct | D24: USD 6 | E24: 16th April 2026
B25: USA Inland IPI Service additional | C25: Gateway | D25: USD 6 | E25: 16th April 2026
B26: Canada | C26: Direct | D26: USD 6 | E26: 16th March 2026
B27: All UK Origins | C27: Direct | D27: USD 6 | E27: 16th March 2026
B28: Europe | C28: Direct | D28: USD 8 | E28: 16th March 2026
B29: China, Hong Kong, Japan | C29: Direct | D29: USD 10 | E29: 16th March 2026
B30: New Zealand | C30: Direct | D30: USD 7 | E30: 30th March 2026
B31: Papua New Guinea | C31: Direct | D31: USD 20 | E31: 28th May 2026
B32: Singapore | C32: Direct | D32: USD 6 | E32: 16th March 2026
B33: Malaysia, Indonesia, Thailand, Vietnam | C33: via Singapore | D33: USD 9 | E33: 16th March 2026
B34: Philippines | C34: via Singapore | D34: USD 10 | E34: 16th March 2026
... B36: All other origins via Singapore | C36: via Singapore | D36: USD 16 | E36: 16th March 2026
B38: High Density
B39: A high-density surcharge will apply for all shipments of 5000 KGS or greater. For these shipments we will charge at a W/M ratio of 1000 KGS = 1.6M3. For example, a 7000 KGS / 6.5M3 shipment will be rated as 7 X 1.6 = 11.2 Rev Tons
B41: High Volume
B42: A High Volume Surcharge will apply as follows, for shipments with volume greater than 20 CBM : 20-25CBM - USD30W/M 25-30CBM - USD35W/M 30-35CBM - USD40W/M 35CBM and above - USD45W/M A High Volume Surcharge of USD 15 per W/M will apply for volumes exceeding 15 CBM via Asia
B44: Heavy Weight Surcharge
B45: The maximum weight acceptance per-shipper-per-shipment is 5 metric tons. Anything above 5 metric tons, high density weight ratio applies. Kindly contact your local Customer Service representative for applicable rate in case your shipment exceeds this limit.
B46: Individual packages of 2500 KGS or greater may be subject to a surcharge. This is available upon request.
B47: Shipments greater than 7000 KGS are subject to acceptance and we reserve the right to split over multiple containers / sailings or HBLs
B49: Heavy Weight Surcharge (China and Hong Kong)
B50: An overweight surcharge of USD5 / metric tonne applies for all shipments where 1000kgs > 1cbm
B52: Heavy Lift Surcharge (shipments via Singapore)
B53: Surcharge of USD$150.00 per B/L is applicable for cargo moving via Singapore with weight of more than 3 tonne per package.
... B66: The following countries have been categorised as target risk countries:
...

Sheet Routing Order
B1: Routing Order | H1: Vanguard Logistics Import LCL Tariff
B4: Enter Origin Port Here® | E4: Aarhus | H4: =VLOOKUP(E4,B44:I152,2,FALSE) -> Denmark
G7: Routing Order
C8: Date:
C9: Supplier:
C10: Contact:
C11: Address:
C12: City:
C13: Country:
C14: Phone:
C15: Email:
C17: Dear Sir / Madam,
C18: =CONCATENATE("We wish to advise that we have made special arrangements with Vanguard Logistics Group Australia for the handling of our ocean freight shipments from ",H4,".") -> We wish to advise that we have made special arrangements with Vanguard Logistics Group Australia for the handling of our ocean freight shipments from Denmark .
C19: Until further notice, please consign all future orders through the Vanguard Logistics Group office at:
C21: Agent Name: | E21: =VLOOKUP(E4,B44:I154,3,FALSE) -> Greencarrier
C22: Address: | E22: =VLOOKUP(E4,B44:I155,4,FALSE) -> Nyhavn 16, 2nd Floor DK-1051 Copenhagen K, Denmark
C23: Contact: | E23: =VLOOKUP(E4,B44:I155,5,FALSE) -> Janni Hartmann
C24: Phone: | E24: =VLOOKUP(E4,B44:I155,6,FALSE) -> +45 77330600
C25: Email: | E25: =VLOOKUP(E4,B44:I155,7,FALSE) -> export.gcc.se@greencarrier.com ; Janni.Hartmann@greencarrier.com
C28: Yours Faithfully,
C32: Signature | H32: Date
C34: Company:
C35: Contact:
C36: Address:
C37: City:
C38: Country:
C39: Phone:
B44: Port | C44: Country | D44: Company | E44: Address | F44: Contact | G44: Phone | H44: email
B46: Chittagong | C46: Bangladesh | D46: Vanguard Logistics Services | E46: Monjur Building (1st Floor), 67 Agrabad C/A Agrabad, Chattogram-4100, Bangladesh | F46: Mizanur Rahman Kanchan Shill | G46: +880 9638 88 55 77 | H46: mizanur.rahman@vanguardlogistics.com kanchan.shill@vanguardlogistics.com
B47: Antwerp | C47: Belgium | D47: Vanguard Logistics Services | E47: Romeynsweel 8, 2030, Antwerpen | F47: Eva Bervoets | G47: +32 3 543 1800 | H47: eva.bervoets​@vanguardlogistics.com
B48: Santos | C48: Brazil | D48: Vanguard Logistics Services | E48: Av. Ana Costa, 433 – Cj 93 and 94 Gonzaga CEP 11060-003 Santos - SP, Brazil | F48: Maria Pilar | G48: +55 13 3229 7000 | H48: maria.pilar​@vanguardlogistics.com
B49: Phnom Penh | C49: Cambodia | D49: Vanguard Logistics Services (Cambodia) Pte Ltd | E49: No 4, Street 242, Sangkat Beungprolit, Khan 7 Makara, Phnom Penh, Cambodia | F49: Mr Ly Uy Ly | G49: 855-11 828388 | H49: ly.uyly@vls-cambodia.com
B50: Sihanoukville | C50: Cambodia | D50: Vanguard Logistics Services (Cambodia) Pte Ltd | E50: No 4, Street 242, Sangkat Beungprolit, Khan 7 Makara, Phnom Penh, Cambodia | F50: Mr Ly Uy Ly | G50: 855-11 828388 | H50: ly.uyly@vls-cambodia.com
B51: Montreal | C51: Canada | D51: Vanguard Logistics Services | E51: 465 Rue St-Jean, #700 Montreal,QC Canada H2Y 2R6 | F51: Operations | G51: +1 438 260 1832 | H51: exports.ca@vanguardlogistics.com antoinette.de.rosa@vanguardlogistics.com
B52: Toronto | C52: Canada | D52: Vanguard Logistics Services | E52: 1450 Meyerside Drive, Suite 402 Mississauga, Ontario Canada L5T 2 N5 Toronto | F52: Operations / Ashima Mehta | G52: +1 905 234 1650 | H52: exports.ca@vanguardlogistics.com ashima.mehta@vanguardlogistics.com
B53: Vancouver | C53: Canada | D53: Vanguard Logistics Services | E53: 1450 Meyerside Drive, Suite 402 Mississauga, Ontario Canada L5T 2 N5 Toronto | F53: Ashima Mehta | G53: +1 905-234-1650 | H53: exports.ca@vanguardlogistics.com ashima.mehta​@vanguardlogistics.com
B54: Dalian | C54: China | D54: Vanguard Logistics Services | E54: 20 Yide Street, Zhongshan District, Dalian 116001, China | F54: Mavis Li | G54: +86 411 3986 7765 | H54: mavis.li@vanguardlogistics.com
B55: Foshan | C55: China | D55: Vanguard Logistics Services | E55: Room 2003-2008, Guidu Building, No. 3007 Chunfeng Rd., Shenzhen, 518002 China | F55: Aly Zhong | G55: 8675582316764 | H55: aly.zhong​@vanguardlogistics.com
B56: Fuzhou | C56: China | D56: Vanguard Logistics Services | E56: Room 1621-1622, 3rd Building, Dong Er Huan Thaihot Plaza 11 Hengyu Road, Jin’an District, Fuzhou, Fujian, China 350011 | F56: Jessie Huang | G56: 86-591-8781 0020 | H56: jessie.huang@vanguardlogistics.com
B57: Guangzhou | C57: China | D57: Vanguard Logistics Services (Zhuhai) Ltd. - Guangzhou Branch | E57: Room 2201-7 Baihui Plaza, No. 193 Zhongshan 5 Road, Yuexiu District, Guangzhou, P.R.China 510030 | F57: Apple Dong | G57: 86-20-8364 9686 | H57: apple.dong@vanguardlogistics.com
...

Sheet IMO2020 Surcharges
B1: IMO2020 Surcharges | D1: Vanguard Logistics LCL Import Tariff
B4: IMO2020 Surcharge Validity | D4: 01 July 26 - 30 September 26
B5: Origin or Via Country / Region | D5: Currency | E5: Amount per w/m
B6: New Zealand | D6: USD | E6: 15
B7: Asia (excluding Korea & Taiwan) | D7: USD | E7: 3
B8: Korea - Sydney / Melbourne (Maxpeed Korea) | D8: USD | E8: 3
B9: Korea - Fremantle / Adelaide / Brisbane (Maxpeed Korea) | D9: USD | E9: 3
B10: Taiwan (Oriental Vanguard Logistics) | D10: USD | E10: 3
B11: Middle East and India Sub-Continent | D11: USD | E11: 0
B12: USA | D12: USD | E12: 6
B13: Israel (JTI Joint Transport International) | D13: USD | E13: 0
B14: Portugal (Allways Cargo) | D14: USD | E14: 0
B15: South Africa | D15: USD | E15: 5
B16: Rest Of World | D16: USD | E16: 0
B17: IMO2020 Surcharges are subject to change based on market fluctuations

Sheet Rate Search
B1: Rate Search | L1: Vanguard Logistics LCL Import Tariff
B4: Use this table to obtain an Import LCL rate
B7: Enter Origin Port Here ® | D7: Shanghai | H7: {=IFERROR(INDEX(Tariff!$B$7:$AA$554,MATCH($D$7,Tariff!$G$7:$G$554,0)+0,MATCH("Country",Tariff!$B$7:$AA$7,0)),"")} -> China | L7: =VLOOKUP(D7,Tariff!G7:J554,4,FALSE) -> CNSHG
C10: Rates | L10: Service Details
B11: Destination | C11: Currency | D11: Rate per cbm | E11: Rate per tonne | F11: Minimum Charge | G11: GRI per w/m | H11: PSS per w/m | I11: IMO2020 per w/m | J11: BAF/EFS per w/m | K11: ETS per w/m | L11: Service Type | M11: via Port | N11: Transit Time | O11: Frequency | P11: Validity
B12: {=IF($D$7=IFERROR(INDEX(Tariff!$B$7:$AA$554,MATCH($D$7,Tariff!$G$7:$G$554,0)+0,MATCH("Origin Port",Tariff!$B$7:$AA$7,0)),""),IFERROR(INDEX(Tariff!$B$7:$AA$554,MATCH($D$7,Tariff!$G$7:$G$554,0)+0,MATCH("Destination Port",Tariff!$B$7:$AA$7,0)),""),"")} -> Sydney | C12: {=IF($D$7=IFERROR(INDEX(Tariff!$B$7:$AA$554,MATCH($D$7,Tariff!$G$7:$G$554,0)+0,MATCH("Origin Port",Tariff!$B$7:$AA$7,0)),""),IFERROR(INDEX(Tariff!$B$7:$AA$554,MATCH($D$7,Tariff!$G$7:$G$554,0)+0,MATCH(C11,Tariff!$B$7:$AA$7,0)),""),"")} -> USD | D12: {=IF($D$7=IFERROR(INDEX(Tariff!$B$7:$AA$554,MATCH($D$7,Tariff!$G$7:$G$554,0)+0,MATCH("Origin Port",Tariff!$B$7:$AA$7,0)),""),IFERROR(INDEX(Tariff!$B$7:$AA$554,MATCH($D$7,Tariff!$G$7:$G$554,0)+0,MATCH(D11,Tariff!$B$7:$AA$7,0)),""),"")} -> 40 | E12: {=IF($D$7=IFERROR(INDEX(Tariff!$B$7:$AA$554,MATCH($D$7,Tariff!$G$7:$G$554,0)+0,MATCH("Origin Port",Tariff!$B$7:$AA$7,0)),""),IFERROR(INDEX(Tariff!$B$7:$AA$554,MATCH($D$7,Tariff!$G$7:$G$554,0)+0,MATCH(E11,Tariff!$B$7:$AA$7,0)),""),"")} -> 40 | F12: {=IF($D$7=IFERROR(INDEX(Tariff!$B$7:$AA$554,MATCH($D$7,Tariff!$G$7:$G$554,0)+0,MATCH("Origin Port",Tariff!$B$7:$AA$7,0)),""),IFERROR(INDEX(Tariff!$B$7:$AA$554,MATCH($D$7,Tariff!$G$7:$G$554,0)+0,MATCH(F11,Tariff!$B$7:$AA$7,0)),""),"")} -> 40 | G12: {=IF($D$7=IFERROR(INDEX(Tariff!$B$7:$AA$554,MATCH($D$7,Tariff!$G$7:$G$554,0)+0,MATCH("Origin Port",Tariff!$B$7:$AA$7,0)),""),IFERROR(INDEX(Tariff!$B$7:$AA$554,MATCH($D$7,Tariff!$G$7:$G$554,0)+0,MATCH(G11,Tariff!$B$7:$AA$7,0)),""),"")} -> N/A | H12: {=IF($D$7=IFERROR(INDEX(Tariff!$B$7:$AA$554,MATCH($D$7,Tariff!$G$7:$G$554,0)+0,MATCH("Origin Port",Tariff!$B$7:$AA$7,0)),""),IFERROR(INDEX(Tariff!$B$7:$AA$554,MATCH($D$7,Tariff!$G$7:$G$554,0)+0,MATCH(H11,Tariff!$B$7:$AA$7,0)),""),"")} -> N/A | I12: {=IF($D$7=IFERROR(INDEX(Tariff!$B$7:$AA$554,MATCH($D$7,Tariff!$G$7:$G$554,0)+0,MATCH("Origin Port",Tariff!$B$7:$AA$7,0)),""),IFERROR(INDEX(Tariff!$B$7:$AA$554,MATCH($D$7,Tariff!$G$7:$G$554,0)+0,MATCH(I11,Tariff!$B$7:$AA$7,0)),""),"")} -> 3 | J12: {=IF($D$7=IFERROR(INDEX(Tariff!$B$7:$AA$554,MATCH($D$7,Tariff!$G$7:$G$554,0)+0,MATCH("Origin Port",Tariff!$B$7:$AA$7,0)),""),IFERROR(INDEX(Tariff!$B$7:$AA$554,MATCH($D$7,Tariff!$G$7:$G$554,0)+0,MATCH(J11,Tariff!$B$7:$AA$7,0)),""),"")} -> 10 | ... P12: {=IF($D$7=IFERROR(INDEX(Tariff!$B$7:$AA$554,MATCH($D$7,Tariff!$G$7:$G$554,0)+0,MATCH("Origin Port",Tariff!$B$7:$AA$7,0)),""),IFERROR(INDEX(Tariff!$B$7:$AA$554,MATCH($D$7,Tariff!$G$7:$G$554,0)+0,MATCH(P11,Tariff!$B$7:$AA$7,0)),""),"")} -> 46265
B13: {=IF($D$7=IFERROR(INDEX(Tariff!$B$7:$AA$554,MATCH($D$7,Tariff!$G$7:$G$554,0)+1,MATCH("Origin Port",Tariff!$B$7:$AA$7,0)),""),IFERROR(INDEX(Tariff!$B$7:$AA$554,MATCH($D$7,Tariff!$G$7:$G$554,0)+1,MATCH("Destination Port",Tariff!$B$7:$AA$7,0)),""),"")} -> Melbourne | C13: {=IF($D$7=IFERROR(INDEX(Tariff!$B$7:$AA$554,MATCH($D$7,Tariff!$G$7:$G$554,0)+1,MATCH("Origin Port",Tariff!$B$7:$AA$7,0)),""),IFERROR(INDEX(Tariff!$B$7:$AA$554,MATCH($D$7,Tariff!$G$7:$G$554,0)+1,MATCH(C11,Tariff!$B$7:$AA$7,0)),""),"")} -> USD | D13: {=IF($D$7=IFERROR(INDEX(Tariff!$B$7:$AA$554,MATCH($D$7,Tariff!$G$7:$G$554,0)+1,MATCH("Origin Port",Tariff!$B$7:$AA$7,0)),""),IFERROR(INDEX(Tariff!$B$7:$AA$554,MATCH($D$7,Tariff!$G$7:$G$554,0)+1,MATCH(D11,Tariff!$B$7:$AA$7,0)),""),"")} -> 38 | E13: {=IF($D$7=IFERROR(INDEX(Tariff!$B$7:$AA$554,MATCH($D$7,Tariff!$G$7:$G$554,0)+1,MATCH("Origin Port",Tariff!$B$7:$AA$7,0)),""),IFERROR(INDEX(Tariff!$B$7:$AA$554,MATCH($D$7,Tariff!$G$7:$G$554,0)+1,MATCH(E11,Tariff!$B$7:$AA$7,0)),""),"")} -> 38 | F13: {=IF($D$7=IFERROR(INDEX(Tariff!$B$7:$AA$554,MATCH($D$7,Tariff!$G$7:$G$554,0)+1,MATCH("Origin Port",Tariff!$B$7:$AA$7,0)),""),IFERROR(INDEX(Tariff!$B$7:$AA$554,MATCH($D$7,Tariff!$G$7:$G$554,0)+1,MATCH(F11,Tariff!$B$7:$AA$7,0)),""),"")} -> 38 | G13: {=IF($D$7=IFERROR(INDEX(Tariff!$B$7:$AA$554,MATCH($D$7,Tariff!$G$7:$G$554,0)+1,MATCH("Origin Port",Tariff!$B$7:$AA$7,0)),""),IFERROR(INDEX(Tariff!$B$7:$AA$554,MATCH($D$7,Tariff!$G$7:$G$554,0)+1,MATCH(G11,Tariff!$B$7:$AA$7,0)),""),"")} -> N/A | H13: {=IF($D$7=IFERROR(INDEX(Tariff!$B$7:$AA$554,MATCH($D$7,Tariff!$G$7:$G$554,0)+1,MATCH("Origin Port",Tariff!$B$7:$AA$7,0)),""),IFERROR(INDEX(Tariff!$B$7:$AA$554,MATCH($D$7,Tariff!$G$7:$G$554,0)+1,MATCH(H11,Tariff!$B$7:$AA$7,0)),""),"")} -> N/A | I13: {=IF($D$7=IFERROR(INDEX(Tariff!$B$7:$AA$554,MATCH($D$7,Tariff!$G$7:$G$554,0)+1,MATCH("Origin Port",Tariff!$B$7:$AA$7,0)),""),IFERROR(INDEX(Tariff!$B$7:$AA$554,MATCH($D$7,Tariff!$G$7:$G$554,0)+1,MATCH(I11,Tariff!$B$7:$AA$7,0)),""),"")} -> 3 | J13: {=IF($D$7=IFERROR(INDEX(Tariff!$B$7:$AA$554,MATCH($D$7,Tariff!$G$7:$G$554,0)+1,MATCH("Origin Port",Tariff!$B$7:$AA$7,0)),""),IFERROR(INDEX(Tariff!$B$7:$AA$554,MATCH($D$7,Tariff!$G$7:$G$554,0)+1,MATCH(J11,Tariff!$B$7:$AA$7,0)),""),"")} -> 10 | ... P13: {=IF($D$7=IFERROR(INDEX(Tariff!$B$7:$AA$554,MATCH($D$7,Tariff!$G$7:$G$554,0)+1,MATCH("Origin Port",Tariff!$B$7:$AA$7,0)),""),IFERROR(INDEX(Tariff!$B$7:$AA$554,MATCH($D$7,Tariff!$G$7:$G$554,0)+1,MATCH(P11,Tariff!$B$7:$AA$7,0)),""),"")} -> 46265
B14: {=IF($D$7=IFERROR(INDEX(Tariff!$B$7:$AA$554,MATCH($D$7,Tariff!$G$7:$G$554,0)+2,MATCH("Origin Port",Tariff!$B$7:$AA$7,0)),""),IFERROR(INDEX(Tariff!$B$7:$AA$554,MATCH($D$7,Tariff!$G$7:$G$554,0)+2,MATCH("Destination Port",Tariff!$B$7:$AA$7,0)),""),"")} -> Fremantle | C14: {=IF($D$7=IFERROR(INDEX(Tariff!$B$7:$AA$554,MATCH($D$7,Tariff!$G$7:$G$554,0)+2,MATCH("Origin Port",Tariff!$B$7:$AA$7,0)),""),IFERROR(INDEX(Tariff!$B$7:$AA$554,MATCH($D$7,Tariff!$G$7:$G$554,0)+2,MATCH(C11,Tariff!$B$7:$AA$7,0)),""),"")} -> USD | D14: {=IF($D$7=IFERROR(INDEX(Tariff!$B$7:$AA$554,MATCH($D$7,Tariff!$G$7:$G$554,0)+2,MATCH("Origin Port",Tariff!$B$7:$AA$7,0)),""),IFERROR(INDEX(Tariff!$B$7:$AA$554,MATCH($D$7,Tariff!$G$7:$G$554,0)+2,MATCH(D11,Tariff!$B$7:$AA$7,0)),""),"")} -> 40 | E14: {=IF($D$7=IFERROR(INDEX(Tariff!$B$7:$AA$554,MATCH($D$7,Tariff!$G$7:$G$554,0)+2,MATCH("Origin Port",Tariff!$B$7:$AA$7,0)),""),IFERROR(INDEX(Tariff!$B$7:$AA$554,MATCH($D$7,Tariff!$G$7:$G$554,0)+2,MATCH(E11,Tariff!$B$7:$AA$7,0)),""),"")} -> 40 | F14: {=IF($D$7=IFERROR(INDEX(Tariff!$B$7:$AA$554,MATCH($D$7,Tariff!$G$7:$G$554,0)+2,MATCH("Origin Port",Tariff!$B$7:$AA$7,0)),""),IFERROR(INDEX(Tariff!$B$7:$AA$554,MATCH($D$7,Tariff!$G$7:$G$554,0)+2,MATCH(F11,Tariff!$B$7:$AA$7,0)),""),"")} -> 40 | G14: {=IF($D$7=IFERROR(INDEX(Tariff!$B$7:$AA$554,MATCH($D$7,Tariff!$G$7:$G$554,0)+2,MATCH("Origin Port",Tariff!$B$7:$AA$7,0)),""),IFERROR(INDEX(Tariff!$B$7:$AA$554,MATCH($D$7,Tariff!$G$7:$G$554,0)+2,MATCH(G11,Tariff!$B$7:$AA$7,0)),""),"")} -> N/A | H14: {=IF($D$7=IFERROR(INDEX(Tariff!$B$7:$AA$554,MATCH($D$7,Tariff!$G$7:$G$554,0)+2,MATCH("Origin Port",Tariff!$B$7:$AA$7,0)),""),IFERROR(INDEX(Tariff!$B$7:$AA$554,MATCH($D$7,Tariff!$G$7:$G$554,0)+2,MATCH(H11,Tariff!$B$7:$AA$7,0)),""),"")} -> N/A | I14: {=IF($D$7=IFERROR(INDEX(Tariff!$B$7:$AA$554,MATCH($D$7,Tariff!$G$7:$G$554,0)+2,MATCH("Origin Port",Tariff!$B$7:$AA$7,0)),""),IFERROR(INDEX(Tariff!$B$7:$AA$554,MATCH($D$7,Tariff!$G$7:$G$554,0)+2,MATCH(I11,Tariff!$B$7:$AA$7,0)),""),"")} -> 3 | J14: {=IF($D$7=IFERROR(INDEX(Tariff!$B$7:$AA$554,MATCH($D$7,Tariff!$G$7:$G$554,0)+2,MATCH("Origin Port",Tariff!$B$7:$AA$7,0)),""),IFERROR(INDEX(Tariff!$B$7:$AA$554,MATCH($D$7,Tariff!$G$7:$G$554,0)+2,MATCH(J11,Tariff!$B$7:$AA$7,0)),""),"")} -> 10 | ... P14: {=IF($D$7=IFERROR(INDEX(Tariff!$B$7:$AA$554,MATCH($D$7,Tariff!$G$7:$G$554,0)+2,MATCH("Origin Port",Tariff!$B$7:$AA$7,0)),""),IFERROR(INDEX(Tariff!$B$7:$AA$554,MATCH($D$7,Tariff!$G$7:$G$554,0)+2,MATCH(P11,Tariff!$B$7:$AA$7,0)),""),"")} -> 46265
B15: {=IF($D$7=IFERROR(INDEX(Tariff!$B$7:$AA$554,MATCH($D$7,Tariff!$G$7:$G$554,0)+3,MATCH("Origin Port",Tariff!$B$7:$AA$7,0)),""),IFERROR(INDEX(Tariff!$B$7:$AA$554,MATCH($D$7,Tariff!$G$7:$G$554,0)+3,MATCH("Destination Port",Tariff!$B$7:$AA$7,0)),""),"")} -> Brisbane | C15: {=IF($D$7=IFERROR(INDEX(Tariff!$B$7:$AA$554,MATCH($D$7,Tariff!$G$7:$G$554,0)+3,MATCH("Origin Port",Tariff!$B$7:$AA$7,0)),""),IFERROR(INDEX(Tariff!$B$7:$AA$554,MATCH($D$7,Tariff!$G$7:$G$554,0)+3,MATCH(C11,Tariff!$B$7:$AA$7,0)),""),"")} -> USD | D15: {=IF($D$7=IFERROR(INDEX(Tariff!$B$7:$AA$554,MATCH($D$7,Tariff!$G$7:$G$554,0)+3,MATCH("Origin Port",Tariff!$B$7:$AA$7,0)),""),IFERROR(INDEX(Tariff!$B$7:$AA$554,MATCH($D$7,Tariff!$G$7:$G$554,0)+3,MATCH(D11,Tariff!$B$7:$AA$7,0)),""),"")} -> 33 | E15: {=IF($D$7=IFERROR(INDEX(Tariff!$B$7:$AA$554,MATCH($D$7,Tariff!$G$7:$G$554,0)+3,MATCH("Origin Port",Tariff!$B$7:$AA$7,0)),""),IFERROR(INDEX(Tariff!$B$7:$AA$554,MATCH($D$7,Tariff!$G$7:$G$554,0)+3,MATCH(E11,Tariff!$B$7:$AA$7,0)),""),"")} -> 33 | F15: {=IF($D$7=IFERROR(INDEX(Tariff!$B$7:$AA$554,MATCH($D$7,Tariff!$G$7:$G$554,0)+3,MATCH("Origin Port",Tariff!$B$7:$AA$7,0)),""),IFERROR(INDEX(Tariff!$B$7:$AA$554,MATCH($D$7,Tariff!$G$7:$G$554,0)+3,MATCH(F11,Tariff!$B$7:$AA$7,0)),""),"")} -> 33 | G15: {=IF($D$7=IFERROR(INDEX(Tariff!$B$7:$AA$554,MATCH($D$7,Tariff!$G$7:$G$554,0)+3,MATCH("Origin Port",Tariff!$B$7:$AA$7,0)),""),IFERROR(INDEX(Tariff!$B$7:$AA$554,MATCH($D$7,Tariff!$G$7:$G$554,0)+3,MATCH(G11,Tariff!$B$7:$AA$7,0)),""),"")} -> N/A | H15: {=IF($D$7=IFERROR(INDEX(Tariff!$B$7:$AA$554,MATCH($D$7,Tariff!$G$7:$G$554,0)+3,MATCH("Origin Port",Tariff!$B$7:$AA$7,0)),""),IFERROR(INDEX(Tariff!$B$7:$AA$554,MATCH($D$7,Tariff!$G$7:$G$554,0)+3,MATCH(H11,Tariff!$B$7:$AA$7,0)),""),"")} -> N/A | I15: {=IF($D$7=IFERROR(INDEX(Tariff!$B$7:$AA$554,MATCH($D$7,Tariff!$G$7:$G$554,0)+3,MATCH("Origin Port",Tariff!$B$7:$AA$7,0)),""),IFERROR(INDEX(Tariff!$B$7:$AA$554,MATCH($D$7,Tariff!$G$7:$G$554,0)+3,MATCH(I11,Tariff!$B$7:$AA$7,0)),""),"")} -> 3 | J15: {=IF($D$7=IFERROR(INDEX(Tariff!$B$7:$AA$554,MATCH($D$7,Tariff!$G$7:$G$554,0)+3,MATCH("Origin Port",Tariff!$B$7:$AA$7,0)),""),IFERROR(INDEX(Tariff!$B$7:$AA$554,MATCH($D$7,Tariff!$G$7:$G$554,0)+3,MATCH(J11,Tariff!$B$7:$AA$7,0)),""),"")} -> 10 | ... P15: {=IF($D$7=IFERROR(INDEX(Tariff!$B$7:$AA$554,MATCH($D$7,Tariff!$G$7:$G$554,0)+3,MATCH("Origin Port",Tariff!$B$7:$AA$7,0)),""),IFERROR(INDEX(Tariff!$B$7:$AA$554,MATCH($D$7,Tariff!$G$7:$G$554,0)+3,MATCH(P11,Tariff!$B$7:$AA$7,0)),""),"")} -> 46265
B16: {=IF($D$7=IFERROR(INDEX(Tariff!$B$7:$AA$554,MATCH($D$7,Tariff!$G$7:$G$554,0)+4,MATCH("Origin Port",Tariff!$B$7:$AA$7,0)),""),IFERROR(INDEX(Tariff!$B$7:$AA$554,MATCH($D$7,Tariff!$G$7:$G$554,0)+4,MATCH("Destination Port",Tariff!$B$7:$AA$7,0)),""),"")} -> Adelaide | C16: {=IF($D$7=IFERROR(INDEX(Tariff!$B$7:$AA$554,MATCH($D$7,Tariff!$G$7:$G$554,0)+4,MATCH("Origin Port",Tariff!$B$7:$AA$7,0)),""),IFERROR(INDEX(Tariff!$B$7:$AA$554,MATCH($D$7,Tariff!$G$7:$G$554,0)+4,MATCH(C11,Tariff!$B$7:$AA$7,0)),""),"")} -> USD | D16: {=IF($D$7=IFERROR(INDEX(Tariff!$B$7:$AA$554,MATCH($D$7,Tariff!$G$7:$G$554,0)+4,MATCH("Origin Port",Tariff!$B$7:$AA$7,0)),""),IFERROR(INDEX(Tariff!$B$7:$AA$554,MATCH($D$7,Tariff!$G$7:$G$554,0)+4,MATCH(D11,Tariff!$B$7:$AA$7,0)),""),"")} -> 73 | E16: {=IF($D$7=IFERROR(INDEX(Tariff!$B$7:$AA$554,MATCH($D$7,Tariff!$G$7:$G$554,0)+4,MATCH("Origin Port",Tariff!$B$7:$AA$7,0)),""),IFERROR(INDEX(Tariff!$B$7:$AA$554,MATCH($D$7,Tariff!$G$7:$G$554,0)+4,MATCH(E11,Tariff!$B$7:$AA$7,0)),""),"")} -> 73 | F16: {=IF($D$7=IFERROR(INDEX(Tariff!$B$7:$AA$554,MATCH($D$7,Tariff!$G$7:$G$554,0)+4,MATCH("Origin Port",Tariff!$B$7:$AA$7,0)),""),IFERROR(INDEX(Tariff!$B$7:$AA$554,MATCH($D$7,Tariff!$G$7:$G$554,0)+4,MATCH(F11,Tariff!$B$7:$AA$7,0)),""),"")} -> 73 | G16: {=IF($D$7=IFERROR(INDEX(Tariff!$B$7:$AA$554,MATCH($D$7,Tariff!$G$7:$G$554,0)+4,MATCH("Origin Port",Tariff!$B$7:$AA$7,0)),""),IFERROR(INDEX(Tariff!$B$7:$AA$554,MATCH($D$7,Tariff!$G$7:$G$554,0)+4,MATCH(G11,Tariff!$B$7:$AA$7,0)),""),"")} -> N/A | H16: {=IF($D$7=IFERROR(INDEX(Tariff!$B$7:$AA$554,MATCH($D$7,Tariff!$G$7:$G$554,0)+4,MATCH("Origin Port",Tariff!$B$7:$AA$7,0)),""),IFERROR(INDEX(Tariff!$B$7:$AA$554,MATCH($D$7,Tariff!$G$7:$G$554,0)+4,MATCH(H11,Tariff!$B$7:$AA$7,0)),""),"")} -> N/A | I16: {=IF($D$7=IFERROR(INDEX(Tariff!$B$7:$AA$554,MATCH($D$7,Tariff!$G$7:$G$554,0)+4,MATCH("Origin Port",Tariff!$B$7:$AA$7,0)),""),IFERROR(INDEX(Tariff!$B$7:$AA$554,MATCH($D$7,Tariff!$G$7:$G$554,0)+4,MATCH(I11,Tariff!$B$7:$AA$7,0)),""),"")} -> 3 | J16: {=IF($D$7=IFERROR(INDEX(Tariff!$B$7:$AA$554,MATCH($D$7,Tariff!$G$7:$G$554,0)+4,MATCH("Origin Port",Tariff!$B$7:$AA$7,0)),""),IFERROR(INDEX(Tariff!$B$7:$AA$554,MATCH($D$7,Tariff!$G$7:$G$554,0)+4,MATCH(J11,Tariff!$B$7:$AA$7,0)),""),"")} -> 10 | ... P16: {=IF($D$7=IFERROR(INDEX(Tariff!$B$7:$AA$554,MATCH($D$7,Tariff!$G$7:$G$554,0)+4,MATCH("Origin Port",Tariff!$B$7:$AA$7,0)),""),IFERROR(INDEX(Tariff!$B$7:$AA$554,MATCH($D$7,Tariff!$G$7:$G$554,0)+4,MATCH(P11,Tariff!$B$7:$AA$7,0)),""),"")} -> 46265
B17: {=IF($D$7=IFERROR(INDEX(Tariff!$B$7:$AA$554,MATCH($D$7,Tariff!$G$7:$G$554,0)+5,MATCH("Origin Port",Tariff!$B$7:$AA$7,0)),""),IFERROR(INDEX(Tariff!$B$7:$AA$554,MATCH($D$7,Tariff!$G$7:$G$554,0)+5,MATCH("Destination Port",Tariff!$B$7:$AA$7,0)),""),"")} | C17: {=IF($D$7=IFERROR(INDEX(Tariff!$B$7:$AA$554,MATCH($D$7,Tariff!$G$7:$G$554,0)+5,MATCH("Origin Port",Tariff!$B$7:$AA$7,0)),""),IFERROR(INDEX(Tariff!$B$7:$AA$554,MATCH($D$7,Tariff!$G$7:$G$554,0)+5,MATCH(C11,Tariff!$B$7:$AA$7,0)),""),"")} | D17: {=IF($D$7=IFERROR(INDEX(Tariff!$B$7:$AA$554,MATCH($D$7,Tariff!$G$7:$G$554,0)+5,MATCH("Origin Port",Tariff!$B$7:$AA$7,0)),""),IFERROR(INDEX(Tariff!$B$7:$AA$554,MATCH($D$7,Tariff!$G$7:$G$554,0)+5,MATCH(D11,Tariff!$B$7:$AA$7,0)),""),"")} | E17: {=IF($D$7=IFERROR(INDEX(Tariff!$B$7:$AA$554,MATCH($D$7,Tariff!$G$7:$G$554,0)+5,MATCH("Origin Port",Tariff!$B$7:$AA$7,0)),""),IFERROR(INDEX(Tariff!$B$7:$AA$554,MATCH($D$7,Tariff!$G$7:$G$554,0)+5,MATCH(E11,Tariff!$B$7:$AA$7,0)),""),"")} | F17: {=IF($D$7=IFERROR(INDEX(Tariff!$B$7:$AA$554,MATCH($D$7,Tariff!$G$7:$G$554,0)+5,MATCH("Origin Port",Tariff!$B$7:$AA$7,0)),""),IFERROR(INDEX(Tariff!$B$7:$AA$554,MATCH($D$7,Tariff!$G$7:$G$554,0)+5,MATCH(F11,Tariff!$B$7:$AA$7,0)),""),"")} | G17: {=IF($D$7=IFERROR(INDEX(Tariff!$B$7:$AA$554,MATCH($D$7,Tariff!$G$7:$G$554,0)+5,MATCH("Origin Port",Tariff!$B$7:$AA$7,0)),""),IFERROR(INDEX(Tariff!$B$7:$AA$554,MATCH($D$7,Tariff!$G$7:$G$554,0)+5,MATCH(G11,Tariff!$B$7:$AA$7,0)),""),"")} | H17: {=IF($D$7=IFERROR(INDEX(Tariff!$B$7:$AA$554,MATCH($D$7,Tariff!$G$7:$G$554,0)+5,MATCH("Origin Port",Tariff!$B$7:$AA$7,0)),""),IFERROR(INDEX(Tariff!$B$7:$AA$554,MATCH($D$7,Tariff!$G$7:$G$554,0)+5,MATCH(H11,Tariff!$B$7:$AA$7,0)),""),"")} | I17: {=IF($D$7=IFERROR(INDEX(Tariff!$B$7:$AA$554,MATCH($D$7,Tariff!$G$7:$G$554,0)+5,MATCH("Origin Port",Tariff!$B$7:$AA$7,0)),""),IFERROR(INDEX(Tariff!$B$7:$AA$554,MATCH($D$7,Tariff!$G$7:$G$554,0)+5,MATCH(I11,Tariff!$B$7:$AA$7,0)),""),"")} | J17: {=IF($D$7=IFERROR(INDEX(Tariff!$B$7:$AA$554,MATCH($D$7,Tariff!$G$7:$G$554,0)+5,MATCH("Origin Port",Tariff!$B$7:$AA$7,0)),""),IFERROR(INDEX(Tariff!$B$7:$AA$554,MATCH($D$7,Tariff!$G$7:$G$554,0)+5,MATCH(J11,Tariff!$B$7:$AA$7,0)),""),"")} | ... P17: {=IF($D$7=IFERROR(INDEX(Tariff!$B$7:$AA$554,MATCH($D$7,Tariff!$G$7:$G$554,0)+5,MATCH("Origin Port",Tariff!$B$7:$AA$7,0)),""),IFERROR(INDEX(Tariff!$B$7:$AA$554,MATCH($D$7,Tariff!$G$7:$G$554,0)+5,MATCH(P11,Tariff!$B$7:$AA$7,0)),""),"")}
B18: {=IF($D$7=IFERROR(INDEX(Tariff!$B$7:$AA$554,MATCH($D$7,Tariff!$G$7:$G$554,0)+6,MATCH("Origin Port",Tariff!$B$7:$AA$7,0)),""),IFERROR(INDEX(Tariff!$B$7:$AA$554,MATCH($D$7,Tariff!$G$7:$G$554,0)+6,MATCH("Destination Port",Tariff!$B$7:$AA$7,0)),""),"")} | C18: {=IF($D$7=IFERROR(INDEX(Tariff!$B$7:$AA$554,MATCH($D$7,Tariff!$G$7:$G$554,0)+6,MATCH("Origin Port",Tariff!$B$7:$AA$7,0)),""),IFERROR(INDEX(Tariff!$B$7:$AA$554,MATCH($D$7,Tariff!$G$7:$G$554,0)+6,MATCH(C11,Tariff!$B$7:$AA$7,0)),""),"")} | D18: {=IF($D$7=IFERROR(INDEX(Tariff!$B$7:$AA$554,MATCH($D$7,Tariff!$G$7:$G$554,0)+6,MATCH("Origin Port",Tariff!$B$7:$AA$7,0)),""),IFERROR(INDEX(Tariff!$B$7:$AA$554,MATCH($D$7,Tariff!$G$7:$G$554,0)+6,MATCH(D11,Tariff!$B$7:$AA$7,0)),""),"")} | E18: {=IF($D$7=IFERROR(INDEX(Tariff!$B$7:$AA$554,MATCH($D$7,Tariff!$G$7:$G$554,0)+6,MATCH("Origin Port",Tariff!$B$7:$AA$7,0)),""),IFERROR(INDEX(Tariff!$B$7:$AA$554,MATCH($D$7,Tariff!$G$7:$G$554,0)+6,MATCH(E11,Tariff!$B$7:$AA$7,0)),""),"")} | F18: {=IF($D$7=IFERROR(INDEX(Tariff!$B$7:$AA$554,MATCH($D$7,Tariff!$G$7:$G$554,0)+6,MATCH("Origin Port",Tariff!$B$7:$AA$7,0)),""),IFERROR(INDEX(Tariff!$B$7:$AA$554,MATCH($D$7,Tariff!$G$7:$G$554,0)+6,MATCH(F11,Tariff!$B$7:$AA$7,0)),""),"")} | G18: {=IF($D$7=IFERROR(INDEX(Tariff!$B$7:$AA$554,MATCH($D$7,Tariff!$G$7:$G$554,0)+6,MATCH("Origin Port",Tariff!$B$7:$AA$7,0)),""),IFERROR(INDEX(Tariff!$B$7:$AA$554,MATCH($D$7,Tariff!$G$7:$G$554,0)+6,MATCH(G11,Tariff!$B$7:$AA$7,0)),""),"")} | H18: {=IF($D$7=IFERROR(INDEX(Tariff!$B$7:$AA$554,MATCH($D$7,Tariff!$G$7:$G$554,0)+6,MATCH("Origin Port",Tariff!$B$7:$AA$7,0)),""),IFERROR(INDEX(Tariff!$B$7:$AA$554,MATCH($D$7,Tariff!$G$7:$G$554,0)+6,MATCH(H11,Tariff!$B$7:$AA$7,0)),""),"")} | I18: {=IF($D$7=IFERROR(INDEX(Tariff!$B$7:$AA$554,MATCH($D$7,Tariff!$G$7:$G$554,0)+6,MATCH("Origin Port",Tariff!$B$7:$AA$7,0)),""),IFERROR(INDEX(Tariff!$B$7:$AA$554,MATCH($D$7,Tariff!$G$7:$G$554,0)+6,MATCH(I11,Tariff!$B$7:$AA$7,0)),""),"")} | J18: {=IF($D$7=IFERROR(INDEX(Tariff!$B$7:$AA$554,MATCH($D$7,Tariff!$G$7:$G$554,0)+6,MATCH("Origin Port",Tariff!$B$7:$AA$7,0)),""),IFERROR(INDEX(Tariff!$B$7:$AA$554,MATCH($D$7,Tariff!$G$7:$G$554,0)+6,MATCH(J11,Tariff!$B$7:$AA$7,0)),""),"")} | ... P18: {=IF($D$7=IFERROR(INDEX(Tariff!$B$7:$AA$554,MATCH($D$7,Tariff!$G$7:$G$554,0)+6,MATCH("Origin Port",Tariff!$B$7:$AA$7,0)),""),IFERROR(INDEX(Tariff!$B$7:$AA$554,MATCH($D$7,Tariff!$G$7:$G$554,0)+6,MATCH(P11,Tariff!$B$7:$AA$7,0)),""),"")}
B19: {=IF($D$7=IFERROR(INDEX(Tariff!$B$7:$AA$510,MATCH($D$7,Tariff!$G$7:$G$510,0)+7,MATCH("Origin Port",Tariff!$B$7:$AA$7,0)),""),IFERROR(INDEX(Tariff!$B$7:$AA$510,MATCH($D$7,Tariff!$G$7:$G$510,0)+7,MATCH("Destination Port",Tariff!$B$7:$AA$7,0)),""),"")} | C19: {=IF($D$7=IFERROR(INDEX(Tariff!$B$7:$AA$510,MATCH($D$7,Tariff!$G$7:$G$510,0)+7,MATCH("Origin Port",Tariff!$B$7:$AA$7,0)),""),IFERROR(INDEX(Tariff!$B$7:$AA$510,MATCH($D$7,Tariff!$G$7:$G$510,0)+7,MATCH(C11,Tariff!$B$7:$AA$7,0)),""),"")} | D19: {=IF($D$7=IFERROR(INDEX(Tariff!$B$7:$AA$510,MATCH($D$7,Tariff!$G$7:$G$510,0)+7,MATCH("Origin Port",Tariff!$B$7:$AA$7,0)),""),IFERROR(INDEX(Tariff!$B$7:$AA$510,MATCH($D$7,Tariff!$G$7:$G$510,0)+7,MATCH(D11,Tariff!$B$7:$AA$7,0)),""),"")} | E19: {=IF($D$7=IFERROR(INDEX(Tariff!$B$7:$AA$510,MATCH($D$7,Tariff!$G$7:$G$510,0)+7,MATCH("Origin Port",Tariff!$B$7:$AA$7,0)),""),IFERROR(INDEX(Tariff!$B$7:$AA$510,MATCH($D$7,Tariff!$G$7:$G$510,0)+7,MATCH(E11,Tariff!$B$7:$AA$7,0)),""),"")} | F19: {=IF($D$7=IFERROR(INDEX(Tariff!$B$7:$AA$510,MATCH($D$7,Tariff!$G$7:$G$510,0)+7,MATCH("Origin Port",Tariff!$B$7:$AA$7,0)),""),IFERROR(INDEX(Tariff!$B$7:$AA$510,MATCH($D$7,Tariff!$G$7:$G$510,0)+7,MATCH(F11,Tariff!$B$7:$AA$7,0)),""),"")} | G19: {=IF($D$7=IFERROR(INDEX(Tariff!$B$7:$AA$510,MATCH($D$7,Tariff!$G$7:$G$510,0)+7,MATCH("Origin Port",Tariff!$B$7:$AA$7,0)),""),IFERROR(INDEX(Tariff!$B$7:$AA$510,MATCH($D$7,Tariff!$G$7:$G$510,0)+7,MATCH(G11,Tariff!$B$7:$AA$7,0)),""),"")} | H19: {=IF($D$7=IFERROR(INDEX(Tariff!$B$7:$AA$510,MATCH($D$7,Tariff!$G$7:$G$510,0)+7,MATCH("Origin Port",Tariff!$B$7:$AA$7,0)),""),IFERROR(INDEX(Tariff!$B$7:$AA$510,MATCH($D$7,Tariff!$G$7:$G$510,0)+7,MATCH(H11,Tariff!$B$7:$AA$7,0)),""),"")} | I19: {=IF($D$7=IFERROR(INDEX(Tariff!$B$7:$AA$510,MATCH($D$7,Tariff!$G$7:$G$510,0)+7,MATCH("Origin Port",Tariff!$B$7:$AA$7,0)),""),IFERROR(INDEX(Tariff!$B$7:$AA$510,MATCH($D$7,Tariff!$G$7:$G$510,0)+7,MATCH(I11,Tariff!$B$7:$AA$7,0)),""),"")} | J19: {=IF($D$7=IFERROR(INDEX(Tariff!$B$7:$AA$510,MATCH($D$7,Tariff!$G$7:$G$510,0)+7,MATCH("Origin Port",Tariff!$B$7:$AA$7,0)),""),IFERROR(INDEX(Tariff!$B$7:$AA$510,MATCH($D$7,Tariff!$G$7:$G$510,0)+7,MATCH(J11,Tariff!$B$7:$AA$7,0)),""),"")} | ... P19: {=IF($D$7=IFERROR(INDEX(Tariff!$B$7:$AA$510,MATCH($D$7,Tariff!$G$7:$G$510,0)+7,MATCH("Origin Port",Tariff!$B$7:$AA$7,0)),""),IFERROR(INDEX(Tariff!$B$7:$AA$510,MATCH($D$7,Tariff!$G$7:$G$510,0)+7,MATCH(P11,Tariff!$B$7:$AA$7,0)),""),"")}
B20: {=IF($D$7=IFERROR(INDEX(Tariff!$B$7:$AA$510,MATCH($D$7,Tariff!$G$7:$G$510,0)+8,MATCH("Origin Port",Tariff!$B$7:$AA$7,0)),""),IFERROR(INDEX(Tariff!$B$7:$AA$510,MATCH($D$7,Tariff!$G$7:$G$510,0)+8,MATCH("Destination Port",Tariff!$B$7:$AA$7,0)),""),"")} | C20: {=IF($D$7=IFERROR(INDEX(Tariff!$B$7:$AA$510,MATCH($D$7,Tariff!$G$7:$G$510,0)+8,MATCH("Origin Port",Tariff!$B$7:$AA$7,0)),""),IFERROR(INDEX(Tariff!$B$7:$AA$510,MATCH($D$7,Tariff!$G$7:$G$510,0)+8,MATCH(C11,Tariff!$B$7:$AA$7,0)),""),"")} | D20: {=IF($D$7=IFERROR(INDEX(Tariff!$B$7:$AA$510,MATCH($D$7,Tariff!$G$7:$G$510,0)+8,MATCH("Origin Port",Tariff!$B$7:$AA$7,0)),""),IFERROR(INDEX(Tariff!$B$7:$AA$510,MATCH($D$7,Tariff!$G$7:$G$510,0)+8,MATCH(D11,Tariff!$B$7:$AA$7,0)),""),"")} | E20: {=IF($D$7=IFERROR(INDEX(Tariff!$B$7:$AA$510,MATCH($D$7,Tariff!$G$7:$G$510,0)+8,MATCH("Origin Port",Tariff!$B$7:$AA$7,0)),""),IFERROR(INDEX(Tariff!$B$7:$AA$510,MATCH($D$7,Tariff!$G$7:$G$510,0)+8,MATCH(E11,Tariff!$B$7:$AA$7,0)),""),"")} | F20: {=IF($D$7=IFERROR(INDEX(Tariff!$B$7:$AA$510,MATCH($D$7,Tariff!$G$7:$G$510,0)+8,MATCH("Origin Port",Tariff!$B$7:$AA$7,0)),""),IFERROR(INDEX(Tariff!$B$7:$AA$510,MATCH($D$7,Tariff!$G$7:$G$510,0)+8,MATCH(F11,Tariff!$B$7:$AA$7,0)),""),"")} | G20: {=IF($D$7=IFERROR(INDEX(Tariff!$B$7:$AA$510,MATCH($D$7,Tariff!$G$7:$G$510,0)+8,MATCH("Origin Port",Tariff!$B$7:$AA$7,0)),""),IFERROR(INDEX(Tariff!$B$7:$AA$510,MATCH($D$7,Tariff!$G$7:$G$510,0)+8,MATCH(G11,Tariff!$B$7:$AA$7,0)),""),"")} | H20: {=IF($D$7=IFERROR(INDEX(Tariff!$B$7:$AA$510,MATCH($D$7,Tariff!$G$7:$G$510,0)+8,MATCH("Origin Port",Tariff!$B$7:$AA$7,0)),""),IFERROR(INDEX(Tariff!$B$7:$AA$510,MATCH($D$7,Tariff!$G$7:$G$510,0)+8,MATCH(H11,Tariff!$B$7:$AA$7,0)),""),"")} | I20: {=IF($D$7=IFERROR(INDEX(Tariff!$B$7:$AA$510,MATCH($D$7,Tariff!$G$7:$G$510,0)+8,MATCH("Origin Port",Tariff!$B$7:$AA$7,0)),""),IFERROR(INDEX(Tariff!$B$7:$AA$510,MATCH($D$7,Tariff!$G$7:$G$510,0)+8,MATCH(I11,Tariff!$B$7:$AA$7,0)),""),"")} | J20: {=IF($D$7=IFERROR(INDEX(Tariff!$B$7:$AA$510,MATCH($D$7,Tariff!$G$7:$G$510,0)+8,MATCH("Origin Port",Tariff!$B$7:$AA$7,0)),""),IFERROR(INDEX(Tariff!$B$7:$AA$510,MATCH($D$7,Tariff!$G$7:$G$510,0)+8,MATCH(J11,Tariff!$B$7:$AA$7,0)),""),"")} | ... P20: {=IF($D$7=IFERROR(INDEX(Tariff!$B$7:$AA$510,MATCH($D$7,Tariff!$G$7:$G$510,0)+8,MATCH("Origin Port",Tariff!$B$7:$AA$7,0)),""),IFERROR(INDEX(Tariff!$B$7:$AA$510,MATCH($D$7,Tariff!$G$7:$G$510,0)+8,MATCH(P11,Tariff!$B$7:$AA$7,0)),""),"")}
B21: {=IF($D$7=IFERROR(INDEX(Tariff!$B$7:$AA$510,MATCH($D$7,Tariff!$G$7:$G$510,0)+9,MATCH("Origin Port",Tariff!$B$7:$AA$7,0)),""),IFERROR(INDEX(Tariff!$B$7:$AA$510,MATCH($D$7,Tariff!$G$7:$G$510,0)+9,MATCH("Destination Port",Tariff!$B$7:$AA$7,0)),""),"")} | C21: {=IF($D$7=IFERROR(INDEX(Tariff!$B$7:$AA$510,MATCH($D$7,Tariff!$G$7:$G$510,0)+9,MATCH("Origin Port",Tariff!$B$7:$AA$7,0)),""),IFERROR(INDEX(Tariff!$B$7:$AA$510,MATCH($D$7,Tariff!$G$7:$G$510,0)+9,MATCH(C11,Tariff!$B$7:$AA$7,0)),""),"")} | D21: {=IF($D$7=IFERROR(INDEX(Tariff!$B$7:$AA$510,MATCH($D$7,Tariff!$G$7:$G$510,0)+9,MATCH("Origin Port",Tariff!$B$7:$AA$7,0)),""),IFERROR(INDEX(Tariff!$B$7:$AA$510,MATCH($D$7,Tariff!$G$7:$G$510,0)+9,MATCH(D11,Tariff!$B$7:$AA$7,0)),""),"")} | E21: {=IF($D$7=IFERROR(INDEX(Tariff!$B$7:$AA$510,MATCH($D$7,Tariff!$G$7:$G$510,0)+9,MATCH("Origin Port",Tariff!$B$7:$AA$7,0)),""),IFERROR(INDEX(Tariff!$B$7:$AA$510,MATCH($D$7,Tariff!$G$7:$G$510,0)+9,MATCH(E11,Tariff!$B$7:$AA$7,0)),""),"")} | F21: {=IF($D$7=IFERROR(INDEX(Tariff!$B$7:$AA$510,MATCH($D$7,Tariff!$G$7:$G$510,0)+9,MATCH("Origin Port",Tariff!$B$7:$AA$7,0)),""),IFERROR(INDEX(Tariff!$B$7:$AA$510,MATCH($D$7,Tariff!$G$7:$G$510,0)+9,MATCH(F11,Tariff!$B$7:$AA$7,0)),""),"")} | G21: {=IF($D$7=IFERROR(INDEX(Tariff!$B$7:$AA$510,MATCH($D$7,Tariff!$G$7:$G$510,0)+9,MATCH("Origin Port",Tariff!$B$7:$AA$7,0)),""),IFERROR(INDEX(Tariff!$B$7:$AA$510,MATCH($D$7,Tariff!$G$7:$G$510,0)+9,MATCH(G11,Tariff!$B$7:$AA$7,0)),""),"")} | H21: {=IF($D$7=IFERROR(INDEX(Tariff!$B$7:$AA$510,MATCH($D$7,Tariff!$G$7:$G$510,0)+9,MATCH("Origin Port",Tariff!$B$7:$AA$7,0)),""),IFERROR(INDEX(Tariff!$B$7:$AA$510,MATCH($D$7,Tariff!$G$7:$G$510,0)+9,MATCH(H11,Tariff!$B$7:$AA$7,0)),""),"")} | I21: {=IF($D$7=IFERROR(INDEX(Tariff!$B$7:$AA$510,MATCH($D$7,Tariff!$G$7:$G$510,0)+9,MATCH("Origin Port",Tariff!$B$7:$AA$7,0)),""),IFERROR(INDEX(Tariff!$B$7:$AA$510,MATCH($D$7,Tariff!$G$7:$G$510,0)+9,MATCH(I11,Tariff!$B$7:$AA$7,0)),""),"")} | J21: {=IF($D$7=IFERROR(INDEX(Tariff!$B$7:$AA$510,MATCH($D$7,Tariff!$G$7:$G$510,0)+9,MATCH("Origin Port",Tariff!$B$7:$AA$7,0)),""),IFERROR(INDEX(Tariff!$B$7:$AA$510,MATCH($D$7,Tariff!$G$7:$G$510,0)+9,MATCH(J11,Tariff!$B$7:$AA$7,0)),""),"")} | ... P21: {=IF($D$7=IFERROR(INDEX(Tariff!$B$7:$AA$510,MATCH($D$7,Tariff!$G$7:$G$510,0)+9,MATCH("Origin Port",Tariff!$B$7:$AA$7,0)),""),IFERROR(INDEX(Tariff!$B$7:$AA$510,MATCH($D$7,Tariff!$G$7:$G$510,0)+9,MATCH(P11,Tariff!$B$7:$AA$7,0)),""),"")}
C24: Note: Please refer to the Conditions tab
C25: {=IFERROR(INDEX(Tariff!$B$7:$AA$554,MATCH($D$7,Tariff!$G$7:$G$554,0)+0,MATCH("Conditions",Tariff!$B$7:$AA$7,0)),"")} -> Subject to applicable GRI, PSS, EFS
B26: vanguardlogistics.com

Sheet Cartage
B1: LCL Cartage | F1: Vanguard Logistics LCL Import Tariff
B4: Australia Cartage Rates
B7: Cartage Rates
B8: Description | C8: Sydney | D8: Melbourne | E8: Brisbane | F8: Adelaide | G8: Fremantle
B9: Metro Delivery, per w/m | C9: 28 | D9: 30 | E9: 28 | F9: 26 | G9: 30
B10: Minimum Charge | C10: 115 | D10: 120 | E10: 115 | F10: 115 | G10: 110
B11: Fuel Surcharge | C11: 0.33 | D11: 0.365 | E11: 0.32 | F11: 0.495 | G11: 0.4162
B12: Toll Surcharge | C12: 0.08 | D12: 0.064 | E12: 0.08 | F12: 0 | G12: 0
B13: Booking Fee | C13: 45 | D13: 45 | E13: 45 | F13: 45 | G13: 45
B14: Hazardous Surcharge | C14: $75.00 max 3 cbm | D14: 70 | E14: $125.00 max 3 cbm | F14: 60 | G14: on app.
B15: Conditions:
B16: * All rates in AUD
B17: * Fuel and Toll surcharges are calculated on the total cartage amount
B18: * Rates are valid for normal trailer and kerbside delivery only
B19: * Hazardous Surcharge is subject to approval
B20: * The above rates are not valid for personal effects
B21: * Demurrage charges may apply
B22: * Fuel Surcharge is subject to change without notice
B23: * Subject to GST
B24: ***IMPORTANT NOTE: Any cargo that is over 3 metres long is quoted on a case by case basis.

Sheet Prepaid Local Charges
B1: Local Charges | K1: Vanguard Logistics Import LCL Tariff
B2: Vanguard Wholesale Australian LCL Destination Charges
I4: Destination
B5: Origin | C5: Charge | D5: Charge Code | E5: Charge per | F5: Currency | G5: Sydney | H5: Melbourne | I5: Fremantle | J5: Brisbane | K5: Adelaide
B6: China | C6: Port Service Charge | D6: PSC | E6: w/m | F6: AUD | G6: 127 | H6: 130 | I6: 130 | J6: 127 | K6: 129
C7: Delivery Order | D7: DO | E7: BL | F7: AUD | G7: 65 | H7: 65 | I7: 65 | J7: 65 | K7: 65
B9: Asia ( Exluding China) | C9: Port Service Charge | D9: PSC | E9: w/m | F9: AUD | G9: 117 | H9: 120 | I9: 120 | J9: 117 | K9: 119
C10: Delivery Order | D10: DO | E10: BL | F10: AUD | G10: 65 | H10: 65 | I10: 65 | J10: 65 | K10: 65
B12: New Zealand | C12: Port Service Charge | D12: PSC | E12: w/m | F12: AUD | G12: 72 | H12: 75 | I12: 75 | J12: 72 | K12: 74
C13: Delivery Order | D13: DO | E13: BL | F13: AUD | G13: 65 | H13: 65 | I13: 65 | J13: 65 | K13: 65
B15: USA | C15: Port Service Charge | D15: PSC | E15: w/m | F15: AUD | G15: 75 | H15: 78 | I15: 78 | J15: 75 | K15: 77
C16: Delivery Order | D16: DO | E16: BL | F16: AUD | G16: 64 | H16: 64 | I16: 64 | J16: 64 | K16: 64
B18: United Kingdom | C18: Port Service Charge | D18: PSC | E18: w/m | F18: AUD | G18: 82 | H18: 85 | I18: 95 | J18: 92 | K18: 94
C19: Delivery Order | D19: DO | E19: BL | F19: AUD | G19: 45 | H19: 45 | I19: 45 | J19: 45 | K19: 45
B20: Europe Direct | C20: Port Service Charge | D20: PSC | E20: w/m | F20: AUD | G20: 102 | H20: 105
C21: Delivery Order | D21: DO | E21: BL | F21: AUD | G21: 65 | H21: 65
B23: Europe Via Asia | C23: Port Service Charge | D23: PSC | E23: w/m | F23: AUD | G23: 112 | H23: 115 | I23: 115 | J23: 112 | K23: 114
C24: Delivery Order | D24: DO | E24: BL | F24: AUD | G24: 65 | H24: 65 | I24: 65 | J24: 65 | K24: 65
B26: Rest of World Direct | C26: Port Service Charge | D26: PSC | E26: w/m | F26: AUD | G26: 107 | H26: 110 | I26: 110 | J26: 107 | K26: 109
C27: Delivery Order | D27: DO | E27: BL | F27: AUD | G27: 65 | H27: 65 | I27: 65 | J27: 65 | K27: 65
B29: Rest of World via Asia | C29: Port Service Charge | D29: PSC | E29: w/m | F29: AUD | G29: 117 | H29: 120 | I29: 20 | J29: 117 | K29: 119
C30: Delivery Order | D30: DO | E30: BL | F30: AUD | G30: 65 | H30: 65 | I30: 65 | J30: 65 | K30: 65
B32: All | C32: BMSB Processing Fee* | D32: BMSB | E32: BL | F32: AUD | G32: 35
B33: * The BMSB fee will apply to all cargo arriving in an FAK from a BMSB country, please refer to conditions tab for BMSB countries.

Sheet Collect Local Charges
B1: Local Charges | K1: Vanguard Logistics Import LCL Tariff
B2: Vanguard Wholesale Australian LCL Destination Charges
I4: Destination
B5: Origin | C5: Charge | D5: Charge Code | E5: Charge per | F5: Currency | G5: Sydney | H5: Melbourne | I5: Fremantle | J5: Brisbane | K5: Adelaide
B6: China / Hong Kong | C6: Port Service Charge | D6: PSC | E6: w/m | F6: AUD | G6: 82 | H6: 82 | I6: 82 | J6: 82 | K6: 84
C7: Delivery Order | D7: DO | E7: BL | F7: AUD | G7: 55 | H7: 55 | I7: 55 | J7: 55 | K7: 55
B9: Asia ( Exluding China) | C9: Port Service Charge | D9: PSC | E9: w/m | F9: AUD | G9: 95 | H9: 98 | I9: 98 | J9: 95 | K9: 97
C10: Delivery Order | D10: DO | E10: BL | F10: AUD | G10: 65 | H10: 65 | I10: 65 | J10: 65 | K10: 65
B12: New Zealand | C12: Port Service Charge | D12: PSC | E12: w/m | F12: AUD | G12: 75 | H12: 78 | I12: 78 | J12: 75 | K12: 77
C13: Delivery Order | D13: DO | E13: BL | F13: AUD | G13: 65 | H13: 65 | I13: 65 | J13: 65 | K13: 65
B15: USA | C15: Port Service Charge | D15: PSC | E15: w/m | F15: AUD | G15: 75 | H15: 78 | I15: 75 | J15: 75 | K15: 77
C16: Delivery Order | D16: DO | E16: BL | F16: AUD | G16: 64 | H16: 64 | I16: 64 | J16: 64 | K16: 64
B18: United Kingdom | C18: Port Service Charge | D18: PSC | E18: w/m | F18: AUD | G18: 85 | H18: 88 | I18: 98 | J18: 95 | K18: 97
C19: Delivery Order | D19: DO | E19: BL | F19: AUD | G19: 45 | H19: 45 | I19: 45 | J19: 45 | K19: 45
B20: Europe Direct | C20: Port Service Charge | D20: PSC | E20: w/m | F20: AUD | G20: 87 | H20: 89
C21: Delivery Order | D21: DO | E21: BL | F21: AUD | G21: 65 | H21: 65
B23: Europe Via Asia | C23: Port Service Charge | D23: PSC | E23: w/m | F23: AUD | G23: 97 | H23: 99 | I23: 100 | J23: 97 | K23: 99
C24: Delivery Order | D24: DO | E24: BL | F24: AUD | G24: 65 | H24: 65 | I24: 65 | J24: 65 | K24: 65
B26: Rest of World Direct | C26: Port Service Charge | D26: PSC | E26: w/m | F26: AUD | G26: 100 | H26: 103 | I26: 103 | J26: 100 | K26: 102
C27: Delivery Order | D27: DO | E27: BL | F27: AUD | G27: 65 | H27: 65 | I27: 65 | J27: 65 | K27: 65
B29: Rest of World via Asia | C29: Port Service Charge | D29: PSC | E29: w/m | F29: AUD | G29: 110 | H29: 113 | I29: 113 | J29: 110 | K29: 112
C30: Delivery Order | D30: DO | E30: BL | F30: AUD | G30: 65 | H30: 65 | I30: 65 | J30: 65 | K30: 65
B32: All | C32: BMSB Processing Fee* | D32: BMSB | E32: BL | F32: AUD | G32: 35
B33: * The BMSB fee will apply to all cargo arriving in an FAK from a BMSB country, please refer to conditions tab for BMSB countries.

Sheet Agent Search
B1: Vanguard Agents | F1: Vanguard Logistics Import LCL Tariff
B4: Search for a Vanguard agent
B7: Enter Origin Port Here ® | C7: Aarhus | G7: =IF(C7="","",(INDEX($B$29:$I$148,MATCH($C$7,$B$29:$B$148,),MATCH("Country",$B$29:$H$29,)))) -> Denmark
B10: Company | C10: =INDEX($B$29:$I$148, MATCH($C$7,$B$29:$B$148,), MATCH("Company",$B$29:$H$29,)) -> Greencarrier
B11: Address | C11: =INDEX($B$29:$I$148, MATCH($C$7,$B$29:$B$148,), MATCH("Address",$B$29:$H$29,)) -> Nyhavn 16, 2nd Floor DK-1051 Copenhagen K, Denmark
B12: Contact | C12: =INDEX($B$29:$I$148, MATCH($C$7,$B$29:$B$148,), MATCH("Contact",$B$29:$H$29,)) -> Janni Hartmann
B13: Phone | C13: =INDEX($B$29:$I$148, MATCH($C$7,$B$29:$B$148,), MATCH("Phone",$B$29:$H$29,)) -> +45 77330600
B14: Email | C14: =INDEX($B$29:$I$148, MATCH($C$7,$B$29:$B$148,), MATCH("email",$B$29:$H$29,)) -> export.gcc.se@greencarrier.com ; Janni.Hartmann@greencarrier.com
B29: Port | C29: Country | D29: Company | E29: Address | F29: Contact | G29: Phone | H29: email
B31: Chittagong | C31: Bangladesh | D31: Vanguard Logistics Services | E31: Monjur Building (1st Floor), 67 Agrabad C/A Agrabad, Chattogram-4100, Bangladesh | F31: Mizanur Rahman Kanchan Shill | G31: +880 9638 88 55 77 | H31: mizanur.rahman@vanguardlogistics.com kanchan.shill@vanguardlogistics.com
B32: Antwerp | C32: Belgium | D32: Vanguard Logistics Services | E32: Romeynsweel 8, 2030, Antwerpen | F32: Eva Bervoets | G32: +32 3 543 1800 | H32: eva.bervoets​@vanguardlogistics.com
B33: Santos | C33: Brazil | D33: Vanguard Logistics Services | E33: Av. Ana Costa, 433 – Cj 93 and 94 Gonzaga CEP 11060-003 Santos - SP, Brazil | F33: Maria Pilar | G33: +55 13 3229 7000 | H33: maria.pilar​@vanguardlogistics.com
B34: Phnom Penh | C34: Cambodia | D34: Vanguard Logistics Services (Cambodia) Pte Ltd | E34: No 4, Street 242, Sangkat Beungprolit, Khan 7 Makara, Phnom Penh, Cambodia | F34: Mr Ly Uy Ly | G34: 855-11 828388 | H34: ly.uyly@vls-cambodia.com
B35: Sihanoukville | C35: Cambodia | D35: Vanguard Logistics Services (Cambodia) Pte Ltd | E35: No 4, Street 242, Sangkat Beungprolit, Khan 7 Makara, Phnom Penh, Cambodia | F35: Mr Ly Uy Ly | G35: 855-11 828388 | H35: ly.uyly@vls-cambodia.com
B36: Montreal | C36: Canada | D36: Vanguard Logistics Services | E36: 465 Rue St-Jean, #700 Montreal,QC Canada H2Y 2R6 | F36: Operations | G36: +1 438 260 1832 | H36: exports.ca@vanguardlogistics.com antoinette.de.rosa@vanguardlogistics.com
B37: Toronto | C37: Canada | D37: Vanguard Logistics Services | E37: 1450 Meyerside Drive, Suite 402 Mississauga, Ontario Canada L5T 2 N5 Toronto | F37: Operations / Ashima Mehta | G37: +1 905 234 1650 | H37: exports.ca@vanguardlogistics.com ashima.mehta@vanguardlogistics.com
B38: Vancouver | C38: Canada | D38: Vanguard Logistics Services | E38: 1450 Meyerside Drive, Suite 402 Mississauga, Ontario Canada L5T 2 N5 Toronto | F38: Ashima Mehta | G38: +1 905-234-1650 | H38: exports.ca@vanguardlogistics.com ashima.mehta​@vanguardlogistics.com
B39: Dalian | C39: China | D39: Vanguard Logistics Services | E39: 20 Yide Street, Zhongshan District, Dalian 116001, China | F39: Mavis Li | G39: +86 411 3986 7765 | H39: mavis.li@vanguardlogistics.com
B40: Foshan | C40: China | D40: Vanguard Logistics Services | E40: Room 2003-2008, Guidu Building, No. 3007 Chunfeng Rd., Shenzhen, 518002 China | F40: Aly Zhong | G40: 8675582316764 | H40: aly.zhong​@vanguardlogistics.com
B41: Fuzhou | C41: China | D41: Vanguard Logistics Services | E41: Room 1621-1622, 3rd Building, Dong Er Huan Thaihot Plaza 11 Hengyu Road, Jin’an District, Fuzhou, Fujian, China 350011 | F41: Jessie Huang | G41: 86-591-8781 0020 | H41: jessie.huang@vanguardlogistics.com
B42: Guangzhou | C42: China | D42: Vanguard Logistics Services (Zhuhai) Ltd. - Guangzhou Branch | E42: Room 2201-7 Baihui Plaza, No. 193 Zhongshan 5 Road, Yuexiu District, Guangzhou, P.R.China 510030 | F42: Apple Dong | G42: 86-20-8364 9686 | H42: apple.dong@vanguardlogistics.com
B43: Huangpu | C43: China | D43: Vanguard Logistics Services (Zhuhai) Ltd. - Guangzhou Branch | E43: Room 2201-7 Baihui Plaza, No. 193 Zhongshan 5 Road, Yuexiu District, Guangzhou, P.R.China 510030 | F43: Apple Dong | G43: 86-20-8364 9686 | H43: apple.dong@vanguardlogistics.com
B44: Jiangmen | C44: China | D44: Vanguard Logisitic Services (HK) Ltd | E44: 36/ F Vicwood Plaza, 199 Des Voeux Road Central, Hong Kong | F44: Helen Cheng | G44: 852 3477 0123 | H44: helen.cheng@vanguardlogistics.com
B45: Ningbo | C45: China | D45: Vanguard Logistics Services | E45: 16/F Huanhe Center Block 1 No 168 Anbo Road Jiangdong District, Ningbo | F45: Eileen Tang | G45: +86 574 2766 6088 | H45: eileen.tang@vanguardlogistics.com
B46: Qingdao | C46: China | D46: Vanguard Logistics Services | E46: Unit A, F-H, 25/F, China-R international Mansion 2 Shandong Road Qingdao, China 266071 | F46: Roicy Li | G46: 86-532-8667 6812 | H46: roicy.li​@vanguardlogistics.com
B47: Shanghai | C47: China | D47: Vanguard Logistics Services | E47: 36/F BM Tower 218 Wusong Road Shanghai, China 200080 | F47: Ms Yoyo Zhang | G47: +86 21 2603 6117 | H47: yoyo.zhang@vanguardlogistics.com
B48: Shekou | C48: China | D48: Vanguard Logistics Services | E48: Room 2003-2008, Guidu Building, No. 3007 Chunfeng Rd., Shenzhen, 518002 China | F48: Daisy Zhong | G48: +86 755 8231 6839 | H48: daisy.zhong​@vanguardlogistics.com
B49: Shenzhen | C49: China | D49: Vanguard Logistics Services | E49: Room 2003-2008, Guidu Building, No. 3007 Chunfeng Rd., Shenzhen, 518002 China | F49: Daisy Zhong | G49: +86 755 8231 6839 | H49: daisy.zhong​@vanguardlogistics.com
B50: Shunde | C50: China | D50: Vanguard Logistics Services | E50: Room 2003-2008, Guidu Building, No. 3007 Chunfeng Rd., Shenzhen, 518002 China | F50: Aly Zhong | G50: 8675582316764 | H50: aly.zhong​@vanguardlogistics.com
B51: Tianjin | C51: China | D51: Vanguard Logistics Services | E51: Room 20H 20th Floor Teda Building 256 Jie Fang South Road Tianjin 300042, China | F51: Jenny Sun | G51: +86 22 5995 9312 | H51: jenny.sun@vanguardlogistics.com
B52: Xiamen | C52: China | D52: Vanguard Logistics Services | E52: Room 3001 The Bank Centre No. 189 Xia He Road Xiamen, Fujian, China 361003 | F52: Maggie Tang | G52: 86-592-2688 678 | H52: maggie.tang@vanguardlogistics.com
B53: Xingang | C53: China | D53: Vanguard Logistics Services | E53: Room 20H 20th Floor Teda Building 256 Jie Fang South Road Tianjin 300042, China | F53: Jenny Sun | G53: +86 22 5995 9312 | H53: jenny.sun@vanguardlogistics.com
B54: Yantian | C54: China | D54: Vanguard Logistics Services | E54: Room 2003-2008, Guidu Building, No. 3007 Chunfeng Rd., Shenzhen, 518002 China | F54: Daisy Zhong | G54: +86 755 8231 6839 | H54: daisy.zhong@vanguardlogistics.com
B55: Zhongshan | C55: China | D55: Vanguard Logistics Services | E55: Room 1511, Lihe International Financial Center, 16 Zhongshan 3rd Road, Zhongshan, Guangdong, China 528403 | F55: Kay Ng | G55: 86-760-8866 8707 | H55: kay.ng@vanguardlogistics.com
B56: Zhuhai | C56: China | D56: Vanguard Logisitic Services (HK) Ltd | E56: Units 1-2 and 4, 5th Floor, Production and Processing Center #3 1 Software Park Road, Zhuhai City, Guangdong, China 519080 | F56: Helen Cheng | G56: 852 3477 0123 | H56: helen.cheng@vanguardlogistics.com
B57: Aarhus | C57: Denmark | D57: Greencarrier | E57: Nyhavn 16, 2nd Floor DK-1051 Copenhagen K, Denmark | F57: Janni Hartmann | G57: +45 77330600 | H57: export.gcc.se@greencarrier.com ; Janni.Hartmann@greencarrier.com
B58: Copenhagen | C58: Denmark | D58: Greencarrier | E58: Nyhavn 16, 2nd Floor DK-1051 Copenhagen K, Denmark | F58: Janni Hartmann | G58: +45 77330600 | H58: export.gcc.se@greencarrier.com ; Janni.Hartmann@greencarrier.com
B59: Lautoka | C59: Fiji | D59: Vanguard Logistics Services (Fiji) | E59: 8 Rose Place Vunato Industrial Sub Division Lautoka | F59: Rizuana Begam | G59: (679) 666 0565 | H59: rizuana.begam@vanguardlogistics.com
B60: Suva | C60: Fiji | D60: Vanguard Logistics Services (Fiji) | E60: Lot 1 Foster Road Walubay Suva, Fiji | F60: Sangeeta Singh | G60: (679) 3315286 | H60: sangeeta.singh@vanguardlogistics.com
B61: Helsinki | C61: Finland | D61: Greencarrier | E61: Läkkisepäntie 23 FI-00620 Helsinki, Finland | F61: Nicolas Myrén | G61: +358 400 272 655 | H61: export.gcc.fi@greencarrier.com ; Nicolas.Myren@greencarrier.com
...

Sheet Origin
A1: Aberdeen
A2: Ahmedabad
A3: Antwerp
A4: Atlanta
A5: Auckland
A6: Baltimore
A7: Bangalore
A8: Bangkok
A9: Barcelona
A10: Belawan
A11: Bilbao
A12: Birmingham
... A124: Zhuhai

Sheet Tariff
E1: National Import Tariff | Z1: Vanguard Logistics Import LCL Tariff
E4: Wholesale LCL Tariff
B7: POA-POD-VIA Port | C7: POA-POD | D7: POD-VIA Port | E7: Region | F7: Country | G7: Origin Port | H7: Destination Port | I7: concatenate | J7: Port Code | K7: VIA Port | L7: VIA Country | M7: Service Type | N7: CFS / Gateway | O7: Currency | P7: Rate per cbm | Q7: Rate per tonne | R7: Minimum Charge | S7: GRI per w/m | T7: PSS per w/m | U7: IMO2020 per w/m | V7: BAF/EFS per w/m | W7: ETS per w/m | X7: Transit Time | Y7: Frequency | Z7: Validity | AA7: Conditions
B8: =G8&H8&K8 -> ChittagongSydneySingapore | C8: =G8&H8 -> ChittagongSydney | D8: =H8&K8 -> SydneySingapore | E8: Indian Sub-Continent | F8: Bangladesh | G8: Chittagong | H8: Sydney | I8: ChittagongSydneyTranship | J8: BDCGP | K8: Singapore | L8: Singapore | M8: Tranship | N8: Singapore | O8: USD | P8: 149 | Q8: 149 | R8: 149 | S8: N/A | T8: N/A | U8: 0 | V8: 16 | W8: N/A | X8: 31 | Y8: Weekly | Z8: 46265 | AA8: Subject to applicable GRI, PSS, EFS
B9: =G9&H9&K9 -> ChittagongMelbourneSingapore | C9: =G9&H9 -> ChittagongMelbourne | D9: =H9&K9 -> MelbourneSingapore | E9: Indian Sub-Continent | F9: Bangladesh | G9: Chittagong | H9: Melbourne | I9: ChittagongMelbourneTranship | J9: BDCGP | K9: Singapore | L9: Singapore | M9: Tranship | N9: Singapore | O9: USD | P9: 139 | Q9: 139 | R9: 139 | S9: N/A | T9: N/A | U9: 0 | V9: 16 | W9: N/A | X9: 27 | Y9: Weekly | Z9: 46265 | AA9: Subject to applicable GRI, PSS, EFS
B10: =G10&H10&K10 -> ChittagongFremantleSingapore | C10: =G10&H10 -> ChittagongFremantle | D10: =H10&K10 -> FremantleSingapore | E10: Indian Sub-Continent | F10: Bangladesh | G10: Chittagong | H10: Fremantle | I10: ChittagongFremantleTranship | J10: BDCGP | K10: Singapore | L10: Singapore | M10: Tranship | N10: Singapore | O10: USD | P10: 149 | Q10: 149 | R10: 149 | S10: N/A | T10: N/A | U10: 0 | V10: 16 | W10: N/A | X10: 26 | Y10: Weekly | Z10: 46265 | AA10: Subject to applicable GRI, PSS, EFS
B11: =G11&H11&K11 -> ChittagongBrisbaneSingapore | C11: =G11&H11 -> ChittagongBrisbane | D11: =H11&K11 -> BrisbaneSingapore | E11: Indian Sub-Continent | F11: Bangladesh | G11: Chittagong | H11: Brisbane | I11: ChittagongBrisbaneTranship | J11: BDCGP | K11: Singapore | L11: Singapore | M11: Tranship | N11: Singapore | O11: USD | P11: 139 | Q11: 139 | R11: 139 | S11: N/A | T11: N/A | U11: 0 | V11: 16 | W11: N/A | X11: 27 | Y11: Weekly | Z11: 46265 | AA11: Subject to applicable GRI, PSS, EFS
B12: =G12&H12&K12 -> ChittagongAdelaideSingapore | C12: =G12&H12 -> ChittagongAdelaide | D12: =H12&K12 -> AdelaideSingapore | E12: Indian Sub-Continent | F12: Bangladesh | G12: Chittagong | H12: Adelaide | I12: ChittagongAdelaideTranship | J12: BDCGP | K12: Singapore | L12: Singapore | M12: Tranship | N12: Singapore | O12: USD | P12: 139 | Q12: 139 | R12: 139 | S12: N/A | T12: N/A | U12: 0 | V12: 16 | W12: N/A | X12: 36 | Y12: Weekly | Z12: 46265 | AA12: Subject to applicable GRI, PSS, EFS
B13: =G13&H13&K13 -> AntwerpSydneySingapore | C13: =G13&H13 -> AntwerpSydney | D13: =H13&K13 -> SydneySingapore | E13: Europe | F13: Belgium | G13: Antwerp | H13: Sydney | I13: AntwerpSydneyTranship | J13: BEANR | K13: Singapore | L13: Singapore | M13: Tranship | N13: Singapore | O13: USD | P13: 142 | Q13: 142 | R13: 142 | S13: N/A | T13: N/A | U13: 0 | V13: 16 | W13: 4.5 | X13: 56 | Y13: Weekly | Z13: 46265 | AA13: Subject to applicable GRI, PSS, EFS;Subject to BMSB Treatment conditions
B14: =G14&H14&K14 -> AntwerpMelbourneSingapore | C14: =G14&H14 -> AntwerpMelbourne | D14: =H14&K14 -> MelbourneSingapore | E14: Europe | F14: Belgium | G14: Antwerp | H14: Melbourne | I14: AntwerpMelbourneTranship | J14: BEANR | K14: Singapore | L14: Singapore | M14: Tranship | N14: Singapore | O14: USD | P14: 142 | Q14: 142 | R14: 142 | S14: N/A | T14: N/A | U14: 0 | V14: 16 | W14: 4.5 | X14: 52 | Y14: Weekly | Z14: 46265 | AA14: Subject to applicable GRI, PSS, EFS;Subject to BMSB Treatment conditions
B15: =G15&H15&K15 -> AntwerpFremantleSingapore | C15: =G15&H15 -> AntwerpFremantle | D15: =H15&K15 -> FremantleSingapore | E15: Europe | F15: Belgium | G15: Antwerp | H15: Fremantle | I15: AntwerpFremantleTranship | J15: BEANR | K15: Singapore | L15: Singapore | M15: Tranship | N15: Singapore | O15: USD | P15: 79 | Q15: 79 | R15: 79 | S15: N/A | T15: N/A | U15: 0 | V15: 16 | W15: 4.5 | X15: 51 | Y15: Weekly | Z15: 46265 | AA15: Subject to applicable GRI, PSS, EFS;Subject to BMSB Treatment conditions
B16: =G16&H16&K16 -> AntwerpBrisbaneSingapore | C16: =G16&H16 -> AntwerpBrisbane | D16: =H16&K16 -> BrisbaneSingapore | E16: Europe | F16: Belgium | G16: Antwerp | H16: Brisbane | I16: AntwerpBrisbaneTranship | J16: BEANR | K16: Singapore | L16: Singapore | M16: Tranship | N16: Singapore | O16: USD | P16: 138 | Q16: 138 | R16: 138 | S16: N/A | T16: N/A | U16: 0 | V16: 16 | W16: 4.5 | X16: 52 | Y16: Weekly | Z16: 46265 | AA16: Subject to applicable GRI, PSS, EFS;Subject to BMSB Treatment conditions
B17: =G17&H17&K17 -> AntwerpAdelaideSingapore | C17: =G17&H17 -> AntwerpAdelaide | D17: =H17&K17 -> AdelaideSingapore | E17: Europe | F17: Belgium | G17: Antwerp | H17: Adelaide | I17: AntwerpAdelaideTranship | J17: BEANR | K17: Singapore | L17: Singapore | M17: Tranship | N17: Singapore | O17: USD | P17: 138 | Q17: 138 | R17: 138 | S17: N/A | T17: N/A | U17: 0 | V17: 16 | W17: 4.5 | X17: 61 | Y17: Weekly | Z17: 46265 | AA17: Subject to applicable GRI, PSS, EFS;Subject to BMSB Treatment conditions
B18: =G18&H18&K18 -> SantosSydneySingapore | C18: =G18&H18 -> SantosSydney | D18: =H18&K18 -> SydneySingapore | E18: South America | F18: Brazil | G18: Santos | H18: Sydney | I18: SantosSydneyTranship | J18: BRSSZ | K18: Singapore | L18: Singapore | M18: Tranship | N18: Singapore | O18: USD | P18: 134 | Q18: 134 | R18: 134 | S18: N/A | T18: N/A | U18: 0 | V18: 16 | W18: N/A | X18: 56 | Y18: Weekly | Z18: 46265 | AA18: Subject to applicable GRI, PSS, EFS
B19: =G19&H19&K19 -> SantosMelbourneSingapore | C19: =G19&H19 -> SantosMelbourne | D19: =H19&K19 -> MelbourneSingapore | E19: South America | F19: Brazil | G19: Santos | H19: Melbourne | I19: SantosMelbourneTranship | J19: BRSSZ | K19: Singapore | L19: Singapore | M19: Tranship | N19: Singapore | O19: USD | P19: 134 | Q19: 134 | R19: 134 | S19: N/A | T19: N/A | U19: 0 | V19: 16 | W19: N/A | X19: 52 | Y19: Weekly | Z19: 46265 | AA19: Subject to applicable GRI, PSS, EFS
B20: =G20&H20&K20 -> SantosFremantleSingapore | C20: =G20&H20 -> SantosFremantle | D20: =H20&K20 -> FremantleSingapore | E20: South America | F20: Brazil | G20: Santos | H20: Fremantle | I20: SantosFremantleTranship | J20: BRSSZ | K20: Singapore | L20: Singapore | M20: Tranship | N20: Singapore | O20: USD | P20: 144 | Q20: 144 | R20: 144 | S20: N/A | T20: N/A | U20: 0 | V20: 16 | W20: N/A | X20: 51 | Y20: Weekly | Z20: 46265 | AA20: Subject to applicable GRI, PSS, EFS
B21: =G21&H21&K21 -> SantosBrisbaneSingapore | C21: =G21&H21 -> SantosBrisbane | D21: =H21&K21 -> BrisbaneSingapore | E21: South America | F21: Brazil | G21: Santos | H21: Brisbane | I21: SantosBrisbaneTranship | J21: BRSSZ | K21: Singapore | L21: Singapore | M21: Tranship | N21: Singapore | O21: USD | P21: 134 | Q21: 134 | R21: 134 | S21: N/A | T21: N/A | U21: 0 | V21: 16 | W21: N/A | X21: 52 | Y21: Weekly | Z21: 46265 | AA21: Subject to applicable GRI, PSS, EFS
B22: =G22&H22&K22 -> SantosAdelaideSingapore | C22: =G22&H22 -> SantosAdelaide | D22: =H22&K22 -> AdelaideSingapore | E22: South America | F22: Brazil | G22: Santos | H22: Adelaide | I22: SantosAdelaideTranship | J22: BRSSZ | K22: Singapore | L22: Singapore | M22: Tranship | N22: Singapore | O22: USD | P22: 134 | Q22: 134 | R22: 134 | S22: N/A | T22: N/A | U22: 0 | V22: 16 | W22: N/A | X22: 61 | Y22: Weekly | Z22: 46265 | AA22: Subject to applicable GRI, PSS, EFS
B23: =G23&H23&K23 -> Phnom PenhSydneySingapore | C23: =G23&H23 -> Phnom PenhSydney | D23: =H23&K23 -> SydneySingapore | E23: Asia | F23: Cambodia | G23: Phnom Penh | H23: Sydney | I23: Phnom PenhSydneyTranship | J23: KHPNH | K23: Singapore | L23: Singapore | M23: Tranship | N23: Singapore | O23: USD | P23: 138 | Q23: 138 | R23: 138 | S23: N/A | T23: N/A | U23: 3 | V23: 16 | W23: N/A | X23: 29 | Y23: Weekly | Z23: 46265 | AA23: Subject to applicable GRI, PSS, EFS
B24: =G24&H24&K24 -> Phnom PenhMelbourneSingapore | C24: =G24&H24 -> Phnom PenhMelbourne | D24: =H24&K24 -> MelbourneSingapore | E24: Asia | F24: Cambodia | G24: Phnom Penh | H24: Melbourne | I24: Phnom PenhMelbourneTranship | J24: KHPNH | K24: Singapore | L24: Singapore | M24: Tranship | N24: Singapore | O24: USD | P24: 128 | Q24: 128 | R24: 128 | S24: N/A | T24: N/A | U24: 3 | V24: 16 | W24: N/A | X24: 25 | Y24: Weekly | Z24: 46265 | AA24: Subject to applicable GRI, PSS, EFS
B25: =G25&H25&K25 -> Phnom PenhFremantleSingapore | C25: =G25&H25 -> Phnom PenhFremantle | D25: =H25&K25 -> FremantleSingapore | E25: Asia | F25: Cambodia | G25: Phnom Penh | H25: Fremantle | I25: Phnom PenhFremantleTranship | J25: KHPNH | K25: Singapore | L25: Singapore | M25: Tranship | N25: Singapore | O25: USD | P25: 138 | Q25: 138 | R25: 138 | S25: N/A | T25: N/A | U25: 3 | V25: 16 | W25: N/A | X25: 24 | Y25: Weekly | Z25: 46265 | AA25: Subject to applicable GRI, PSS, EFS
